Workbook

Sheet Weekly Inventory
A1: Column 1 | B1: Vodka | C1: Triple Sec | D1: Rum No. 1 | E1: All Spice Dram | F1: Gin 1 | G1: Gin 2 | H1: Gin 3 | I1: Absinthe No. 1 | J1: Absinthe No. 2 | K1: Absinthe No 3 | L1: Coffee Liqueur | M1: 3 Pepper Vodka | N1: Red Wheat Bourbon | O1: SGS Corn | P1: SGS Red Wheat | Q1: SGS Rye | R1: Spiced Rum | S1: Dark Spiced Rum | T1: Cinnamon Vodka | U1: Peppercorn Vodka | V1: Golden Creme de Menthe | W1: Creme de Cacao | X1: Princess Water | Y1: Ladies Pleasure | Z1: Riga Kummel | AA1: Rum No. 2 | AB1: 5 Tail Whiskey | AC1: White Dog | AD1: Low Entry Bourbon | AE1: SGS Barley | AF1: BlackStrap Rum | AG1: Aged Rum | AH1: Aged Rum No. 1 | AI1: Navy Strength Spiced Rum | AJ1: Rosolio di Rose | AK1: Mid Entry Bourbon | AL1: Krupnik | AM1: Infinity Barrel | AN1: Horseradish Vodka | AO1: Vanilla Liqueur | AP1: Strawberry Liqueur | AQ1: Cherry Ratafia | AR1: Amaretto | AS1: Maraschino | AT1: Lemon Vodka | AU1: Peach Schnapps | AV1: Honey Barrel Corn | AW1: Peppermint Schnapps | AX1: Column 43
A2: 46069 | L2: 39 | R2: 115 | AX2: =SUM(B2:AW2) -> 154
A3: 46059 | F3: 73 | AX3: =SUM(B3:AW3) -> 73
A4: 46042 | AA4: 63 | AX4: =SUM(B4:AW4) -> 63
A5: 46020 | B5: 68 | C5: 31 | D5: 80 | E5: 18 | F5: 0 | G5: 61 | H5: 20 | I5: 10 | J5: 0 | K5: 5 | L5: 17 | M5: 50 | N5: 25 | Q5: 19 | R5: 0 | S5: 3 | T5: 0 | U5: 0 | V5: 10 | W5: 30 | X5: 17 | Y5: 26 | Z5: 9 | AA5: 0 | AB5: 0 | AC5: 17 | AD5: 0 | AE5: 5 | AF5: 0 | AG5: 0 | AH5: 25 | AI5: 0 | AJ5: 17 | AK5: 0 | AL5: 0 | AM5: 0 | AN5: 2 | AO5: 13 | AP5: 4 | AQ5: 28 | AR5: 17 | AS5: 49 | AT5: 0 | AU5: 16 | AV5: 20 | AW5: 32 | AX5: =SUM(B5:AW5) -> 744
A6: 46009 | B6: 80 | G6: 70 | L6: 27 | AX6: =SUM(B6:AU6) -> 177
A7: 45992 | B7: 9 | C7: 40 | D7: 91 | E7: 34 | F7: 6 | G7: 4 | H7: 27 | I7: 14 | J7: 0 | K7: 6 | L7: 6 | M7: 71 | N7: 45 | O7: 0 | P7: 0 | Q7: 31 | R7: 0 | S7: 16 | T7: 1 | U7: 0 | V7: 13 | W7: 33 | X7: 35 | Y7: 36 | Z7: 10 | AA7: 2 | AB7: 0 | AC7: 17 | AD7: 0 | AE7: 7 | AF7: 0 | AG7: 0 | AH7: 27 | AI7: 0 | AJ7: 17 | AK7: 0 | AL7: 7 | AM7: 0 | AN7: 19 | AO7: 15 | AP7: 5 | AQ7: 33 | AR7: 27 | AS7: 49 | AT7: 0 | AU7: 21 | AX7: =SUM(B7:AU7) -> 774
A8: 45991 | D8: 91 | Q8: 31 | X8: 35 | AQ8: 33 | AX8: =SUM(B8:AU8) -> 190
A9: 45973 | B9: 97 | N9: 58 | AL9: 15 | AX9: =SUM(B9:AT9) -> 170
A10: 45936 | B10: 61 | C10: 50 | D10: 10 | E10: 44 | F10: 20 | G10: 22 | H10: 39 | I10: 16 | J10: 0 | K10: 7 | L10: 14 | M10: 95 | N10: 0 | O10: 0 | P10: 0 | Q10: 0 | R10: 11 | S10: 32 | T10: 3 | U10: 0 | V10: 13 | W10: 36 | X10: 2 | Y10: 43 | Z10: 10 | AA10: 7 | AB10: 0 | AC10: 17 | AD10: 0 | AE10: 13 | AF10: 0 | AG10: 7 | AH10: 35 | AI10: 2 | AJ10: 17 | AK10: 0 | AL10: 3 | AM10: 0 | AN10: 26 | AO10: 3 | AP10: 7 | AQ10: 0 | AR10: 40 | AS10: 50 | AT10: 0 | AX10: =SUM(B10:AT10) -> 755
A11: 45929 | B11: 69 | C11: 52 | D11: 21 | E11: 46 | F11: 20 | G11: 23 | H11: 39 | I11: 16 | J11: 0 | K11: 7 | L11: 15 | M11: 96 | N11: 0 | O11: 0 | P11: 0 | Q11: 0 | R11: 14 | S11: 34 | T11: 3 | U11: 0 | V11: 13 | W11: 36 | X11: 2 | Y11: 47 | Z11: 10 | AA11: 7 | AB11: 0 | AC11: 17 | AD11: 0 | AE11: 16 | AF11: 1 | AG11: 7 | AH11: 35 | AI11: 4 | AJ11: 17 | AK11: 0 | AL11: 3 | AM11: 0 | AN11: 28 | AO11: 7 | AP11: 9 | AQ11: 0 | AR11: 47 | AS11: 50 | AT11: 0 | AX11: =SUM(B11:AT11) -> 811
A12: 45928 | B12: 69 | AX12: =SUM(B12:AT12) -> 69
A13: 45922 | B13: 0 | C13: 54 | D13: 24 | E13: 46 | F13: 21 | G13: 25 | H13: 39 | I13: 16 | J13: 0 | K13: 7 | L13: 17 | M13: 98 | N13: 0 | O13: 0 | P13: 0 | Q13: 0 | R13: 15 | S13: 34 | T13: 3 | U13: 0 | V13: 14 | W13: 36 | X13: 2 | Y13: 47 | Z13: 10 | AA13: 7 | AB13: 0 | AC13: 17 | AD13: 0 | AE13: 18 | AF13: 1 | AG13: 7 | AH13: 35 | AI13: 4 | AJ13: 17 | AK13: 0 | AL13: 4 | AM13: 0 | AN13: 31 | AO13: 8 | AP13: 9 | AQ13: 0 | AR13: 47 | AS13: 50 | AT13: 0 | AX13: =SUM(B13:AT13) -> 763
A14: 45921 | C14: 54 | AX14: =SUM(B14:AT14) -> 54
A15: 45904 | B15: 12 | C15: 0 | D15: 27 | E15: 48 | F15: 27 | G15: 37 | H15: 41 | I15: 16 | J15: 0 | K15: 7 | L15: 21 | M15: 103 | N15: 0 | O15: 0 | P15: 0 | Q15: 0 | R15: 20 | S15: 36 | T15: 5 | U15: 0 | V15: 14 | W15: 38 | X15: 5 | Y15: 50 | Z15: 10 | AA15: 11 | AB15: 0 | AC15: 17 | AD15: 0 | AE15: 22 | AF15: 1 | AG15: 7 | AH15: 36 | AI15: 11 | AJ15: 17 | AK15: 0 | AL15: 6 | AM15: 0 | AN15: 31 | AO15: 15 | AP15: 10 | AQ15: 0 | AR15: 54 | AS15: 50 | AT15: 0 | AX15: =SUM(B15:AT15) -> 805
A16: 45903 | M16: 103 | AN16: 31 | AX16: =SUM(B16:AT16) -> 134
A17: 45887 | B17: 33 | C17: 2 | D17: 31 | E17: 51 | F17: 28 | G17: 37 | H17: 41 | I17: 31 | J17: 0 | K17: 7 | L17: 26 | M17: 0 | N17: 0 | O17: 0 | P17: 0 | Q17: 0 | R17: 24 | S17: 40 | T17: 6 | U17: 0 | V17: 14 | W17: 39 | X17: 8 | Y17: 51 | Z17: 10 | AA17: 14 | AB17: 0 | AC17: 17 | AD17: 0 | AE17: 24 | AF17: 1 | AG17: 11 | AH17: 36 | AI17: 11 | AJ17: 17 | AK17: 0 | AL17: 9 | AM17: 0 | AN17: 0 | AO17: 15 | AP17: 10 | AQ17: 0 | AR17: 59 | AS17: 50 | AT17: 0 | AX17: =SUM(B17:AT17) -> 753
A18: 45886 | B18: 33 | I18: 31 | AR18: 59 | AX18: =SUM(B18:AT18) -> 123
A19: 45859 | B19: 3 | C19: 8 | D19: 37 | E19: 52 | F19: 38 | G19: 46 | H19: 46 | I19: 0 | J19: 0 | K19: 10 | L19: 30 | M19: 7 | N19: 0 | O19: 11 | P19: 0 | Q19: 6 | R19: 26 | S19: 44 | T19: 6 | U19: 0 | V19: 15 | W19: 40 | X19: 8 | Y19: 58 | Z19: 10 | AA19: 14 | AB19: 0 | AC19: 17 | AD19: 0 | AE19: 32 | AF19: 1 | AG19: 11 | AH19: 36 | AI19: 13 | AJ19: 17 | AK19: 0 | AL19: 11 | AM19: 8 | AN19: 4 | AO19: 21 | AP19: 15 | AQ19: 0 | AS19: 50 | AT19: 6 | AX19: =SUM(B19:AT19) -> 757
A20: 45858 | D20: 37 | AX20: =SUM(B20:AT20) -> 37
A21: 45847 | B21: 18 | C21: 9 | D21: 0 | E21: 52 | F21: 40 | G21: 47 | H21: 46 | I21: 0 | J21: 0 | K21: 10 | L21: 33 | M21: 15 | N21: 0 | O21: 15 | P21: 0 | Q21: 9 | R21: 26 | S21: 45 | T21: 6 | U21: 0 | V21: 15 | W21: 41 | X21: 8 | Y21: 60 | Z21: 10 | AA21: 15 | AB21: 0 | AC21: 17 | AD21: 0 | AE21: 34 | AF21: 1 | AG21: 11 | AH21: 36 | AI21: 13 | AJ21: 17 | AK21: 0 | AL21: 13 | AM21: 11 | AN21: 6 | AO21: 23 | AP21: 17 | AQ21: 1 | AS21: 50 | AT21: 11 | AX21: =SUM(B21:AT21) -> 781
A22: 45846 | L22: 34 | X22: 8 | AT22: 11 | AX22: =SUM(B22:AT22) -> 53
A23: 45839 | B23: 26 | C23: 9 | D23: 0 | E23: 52 | F23: 42 | G23: 51 | H23: 49 | I23: 0 | J23: 0 | K23: 10 | L23: 0 | M23: 21 | N23: 0 | O23: 17 | P23: 0 | Q23: 11 | R23: 35 | S23: 47 | T23: 6 | U23: 0 | V23: 16 | W23: 41 | Y23: 61 | Z23: 10 | AA23: 20 | AB23: 0 | AC23: 17 | AD23: 0 | AE23: 39 | AF23: 1 | AG23: 12 | AH23: 36 | AI23: 15 | AJ23: 20 | AK23: 0 | AL23: 14 | AM23: 14 | AN23: 6 | AO23: 24 | AP23: 18 | AQ23: 4 | AS23: 51 | AT23: 0 | AX23: =SUM(B23:AT23) -> 795
A24: 45832 | B24: 30 | C24: 12 | D24: 0 | E24: 56 | F24: 42 | G24: 53 | H24: 51 | I24: 0 | J24: 0 | K24: 12 | L24: 0 | M24: 23 | N24: 0 | O24: 19 | P24: 0 | Q24: 12 | R24: 39 | S24: 48 | T24: 6 | U24: 0 | V24: 16 | W24: 41 | Y24: 63 | Z24: 10 | AA24: 24 | AB24: 0 | AC24: 17 | AD24: 0 | AE24: 39 | AF24: 1 | AG24: 12 | AH24: 38 | AI24: 17 | AJ24: 21 | AK24: 0 | AL24: 14 | AM24: 16 | AN24: 7 | AO24: 24 | AP24: 18 | AQ24: 4 | AS24: 51 | AT24: 0 | AX24: =SUM(B24:AT24) -> 836
A25: 45828 | H25: 52 | AX25: =SUM(B25:AS25) -> 52
A26: 45824 | B26: 42 | C26: 14 | D26: 0 | E26: 56 | F26: 43 | G26: 55 | H26: 0 | I26: 0 | J26: 0 | K26: 12 | L26: 2 | M26: 32 | N26: 0 | O26: 20 | P26: 0 | Q26: 12 | R26: 39 | S26: 49 | T26: 6 | U26: 0 | V26: 16 | W26: 41 | Y26: 63 | Z26: 10 | AA26: 25 | AB26: 0 | AC26: 17 | AD26: 0 | AE26: 39 | AF26: 1 | AG26: 12 | AH26: 38 | AI26: 18 | AJ26: 21 | AK26: 0 | AL26: 14 | AM26: 17 | AN26: 7 | AO26: 25 | AP26: 20 | AQ26: 7 | AS26: 51 | AT26: 0 | AX26: =SUM(B26:AT26) -> 824
A27: 45822 | AS27: 54 | AX27: =SUM(B27:AS27) -> 54
A28: 45817 | B28: 46 | C28: 15 | D28: 3 | E28: 56 | F28: 45 | G28: 54 | H28: 0 | I28: 0 | J28: 2 | K28: 12 | L28: 4 | M28: 40 | N28: 0 | O28: 22 | P28: 0 | Q28: 16 | R28: 40 | S28: 49 | T28: 6 | U28: 0 | V28: 16 | W28: 41 | Y28: 65 | Z28: 10 | AA28: 26 | AB28: 0 | AC28: 17 | AD28: 0 | AE28: 39 | AF28: 1 | AG28: 12 | AH28: 38 | AI28: 19 | AJ28: 21 | AK28: 1 | AL28: 15 | AM28: 17 | AN28: 8 | AO28: 25 | AP28: 21 | AQ28: 8 | AS28: 0 | AT28: 0 | AX28: =SUM(B28:AQ28) -> 810
A29: 45810 | B29: 52 | C29: 17 | D29: 3 | E29: 56 | F29: 50 | G29: 57 | H29: 0 | I29: 0 | J29: 2 | K29: 12 | L29: 5 | M29: 41 | N29: 0 | O29: 24 | P29: 0 | Q29: 20 | R29: 41 | S29: 51 | T29: 6 | U29: 0 | V29: 16 | W29: 41 | Y29: 66 | Z29: 10 | AA29: 26 | AB29: 0 | AC29: 17 | AD29: 0 | AE29: 39 | AF29: 1 | AG29: 12 | AH29: 38 | AI29: 19 | AJ29: 21 | AK29: 1 | AL29: 0 | AM29: 18 | AN29: 9 | AO29: 26 | AP29: 21 | AQ29: 9 | AX29: =SUM(B29:AQ29) -> 827
A30: 45803 | B30: 62 | C30: 18 | D30: 5 | E30: 56 | F30: 51 | G30: 57 | H30: 0 | I30: 0 | J30: 2 | K30: 12 | L30: 6 | M30: 42 | N30: 0 | O30: 26 | P30: 0 | Q30: 21 | R30: 44 | S30: 51 | T30: 6 | U30: 0 | V30: 16 | W30: 42 | Y30: 67 | Z30: 10 | AA30: 26 | AB30: 0 | AC30: 17 | AD30: 0 | AE30: 39 | AF30: 2 | AG30: 12 | AH30: 38 | AI30: 20 | AJ30: 21 | AK30: 4 | AL30: 2 | AM30: 20 | AN30: 10 | AO30: 26 | AP30: 21 | AQ30: 9 | AX30: =SUM(B30:AQ30) -> 861
A31: 45800 | B31: 64 | AX31: =SUM(B31:AQ31) -> 64
A32: 45796 | B32: 0 | C32: 20 | D32: 7 | E32: 56 | F32: 53 | G32: 57 | H32: 0 | I32: 0 | J32: 2 | K32: 12 | L32: 9 | M32: 44 | N32: 0 | O32: 27 | P32: 0 | Q32: 23 | R32: 44 | S32: 52 | T32: 6 | U32: 0 | V32: 16 | W32: 43 | Y32: 67 | Z32: 10 | AA32: 27 | AB32: 0 | AC32: 17 | AD32: 0 | AE32: 42 | AF32: 2 | AG32: 12 | AH32: 38 | AI32: 20 | AJ32: 21 | AK32: 9 | AL32: 8 | AM32: 22 | AN32: 11 | AO32: 28 | AP32: 23 | AX32: =SUM(B32:AQ32) -> 828
A33: 45793 | AP33: 24 | AX33: =SUM(B33:AQ33) -> 24
A34: 45789 | B34: 8 | C34: 22 | D34: 8 | E34: 56 | F34: 55 | G34: 59 | H34: 3 | I34: 0 | J34: 3 | K34: 13 | L34: 11 | M34: 47 | N34: 0 | O34: 28 | P34: 0 | Q34: 26 | R34: 49 | S34: 53 | T34: 7 | U34: 0 | V34: 17 | W34: 43 | Y34: 70 | Z34: 11 | AA34: 27 | AB34: 0 | AC34: 17 | AD34: 0 | AE34: 42 | AF34: 2 | AG34: 12 | AH34: 40 | AI34: 20 | AJ34: 21 | AK34: 11 | AL34: 12 | AM34: 30 | AN34: 14 | AO34: 28 | AX34: =SUM(B34:AQ34) -> 865
A35: 45786 | AN35: 15 | AO35: 28 | AX35: =SUM(B35:AQ35) -> 43
A36: 45783 | B36: 14 | C36: 23 | D36: 11 | E36: 56 | F36: 55 | G36: 66 | H36: 3 | I36: 0 | J36: 6 | K36: 14 | L36: 13 | M36: 53 | N36: 0 | O36: 30 | P36: 0 | Q36: 26 | R36: 52 | S36: 53 | T36: 7 | U36: 0 | V36: 18 | W36: 43 | Y36: 70 | Z36: 11 | AA36: 27 | AB36: 0 | AC36: 17 | AD36: 0 | AE36: 42 | AF36: 2 | AG36: 12 | AH36: 40 | AI36: 20 | AJ36: 21 | AK36: 14 | AL36: 15 | AM36: 37 | AX36: =SUM(B36:AQ36) -> 871
A37: 45775 | B37: 21 | C37: 24 | D37: 15 | E37: 56 | F37: 56 | G37: 71 | H37: 3 | I37: 0 | J37: 6 | K37: 14 | L37: 14 | M37: 55 | N37: 0 | O37: 35 | P37: 0 | Q37: 28 | R37: 53 | S37: 52 | T37: 7 | U37: 0 | V37: 19 | W37: 44 | Y37: 71 | Z37: 11 | AA37: 27 | AB37: 0 | AC37: 17 | AD37: 0 | AE37: 44 | AF37: 2 | AG37: 12 | AH37: 40 | AI37: 21 | AJ37: 21 | AK37: 22 | AL37: 15 | AM37: 43 | AX37: =SUM(B37:AQ37) -> 919
A38: 45770 | AM38: 46 | AX38: =SUM(B38:AQ38) -> 46
A39: 45765 | C39: 26 | AL39: 25 | AX39: =SUM(B39:AQ39) -> 51
A40: 45761 | B40: 45 | C40: 0 | D40: 17 | E40: 57 | F40: 59 | G40: 73 | H40: 4 | I40: 0 | J40: 6 | K40: 14 | L40: 16 | M40: 61 | N40: 0 | O40: 39 | P40: 0 | Q40: 39 | R40: 57 | S40: 58 | T40: 7 | U40: 0 | V40: 19 | W40: 46 | Y40: 71 | Z40: 11 | AA40: 27 | AB40: 0 | AC40: 17 | AD40: 0 | AE40: 44 | AF40: 2 | AG40: 12 | AH40: 40 | AI40: 26 | AJ40: 22 | AK40: 35 | AX40: =SUM(B40:AQ40) -> 924
...

Sheet Monthly Usage
A1: Column 1 | B1: Total | C1: Vodka | D1: Triple Sec | E1: Rum | F1: All Spice Dram | G1: Gin 1 | H1: Gin 2 | I1: Gin 3 | J1: Absinthe | K1: Coffee Liqueur | L1: 3 Pepper Vodka | M1: Red Wheat Bourbon | N1: SGS Corn | O1: SGS Red Wheat | P1: SGS Rye | Q1: Spiced Rum | R1: Dark Spiced Rum | S1: Cinnamon Vodke | T1: Peppercorn Vodka | U1: Golden Creme de Menthe | V1: Creme de Cacao | W1: Ladies Pleasure | X1: Riga Kummel | Y1: Absinthe No. 2 | Z1: 5 Tail Whiskey
A2: 45261 | B2: =SUM(C2:I2) -> 26 | C2: ='Weekly Inventory'!B39-'Weekly Inventory'!B41 -> 0 | D2: ='Weekly Inventory'!C39-'Weekly Inventory'!C41 -> 26 | E2: ='Weekly Inventory'!D39-'Weekly Inventory'!D41 -> 0 | G2: ='Weekly Inventory'!F39-'Weekly Inventory'!F41 -> 0 | H2: ='Weekly Inventory'!G39-'Weekly Inventory'!G41 -> 0 | I2: ='Weekly Inventory'!H39-'Weekly Inventory'!H41 -> 0
A3: 45292 | B3: =SUM(C3:I3) -> 198 | C3: ='Weekly Inventory'!B41+'Weekly Inventory'!B45+'Weekly Inventory'!B51-'Weekly Inventory'!B53+'Weekly Inventory'!B52 -> -20 | D3: ='Weekly Inventory'!C41+'Weekly Inventory'!C45+'Weekly Inventory'!C51-'Weekly Inventory'!C53+'Weekly Inventory'!C52 -> 16 | E3: ='Weekly Inventory'!D41+'Weekly Inventory'!D45+'Weekly Inventory'!D51-'Weekly Inventory'!D53+'Weekly Inventory'!D52 -> 39 | F3: ='Weekly Inventory'!E41+'Weekly Inventory'!E45+'Weekly Inventory'!E51-'Weekly Inventory'!E53+'Weekly Inventory'!E52 -> 63 | G3: ='Weekly Inventory'!F41+'Weekly Inventory'!F45+'Weekly Inventory'!F51-'Weekly Inventory'!F53+'Weekly Inventory'!F52 -> 0 | H3: ='Weekly Inventory'!G41+'Weekly Inventory'!G45+'Weekly Inventory'!G51-'Weekly Inventory'!G53+'Weekly Inventory'!G52 -> 97 | I3: ='Weekly Inventory'!H41+'Weekly Inventory'!H45+'Weekly Inventory'!H51-'Weekly Inventory'!H53+'Weekly Inventory'!H52 -> 3 | J3: ='Weekly Inventory'!I41+'Weekly Inventory'!I45+'Weekly Inventory'!I51-'Weekly Inventory'!I53+'Weekly Inventory'!I52 -> 1 | K3: ='Weekly Inventory'!L41+'Weekly Inventory'!L45+'Weekly Inventory'!L51-'Weekly Inventory'!L53+'Weekly Inventory'!L52 -> 33 | L3: ='Weekly Inventory'!M41+'Weekly Inventory'!M45+'Weekly Inventory'!M51-'Weekly Inventory'!M53+'Weekly Inventory'!M52 -> 39
A4: 45323 | B4: =sum(C4:Z4) -> 592 | C4: ='Weekly Inventory'!B53+'Weekly Inventory'!B55+'Weekly Inventory'!B56+'Weekly Inventory'!B57+'Weekly Inventory'!B60-'Weekly Inventory'!B62 -> 153 | D4: ='Weekly Inventory'!C53+'Weekly Inventory'!C55+'Weekly Inventory'!C56+'Weekly Inventory'!C57+'Weekly Inventory'!C60-'Weekly Inventory'!C62 -> 67 | E4: ='Weekly Inventory'!D53+'Weekly Inventory'!D55+'Weekly Inventory'!D56+'Weekly Inventory'!D57+'Weekly Inventory'!D60-'Weekly Inventory'!D62 -> 70 | F4: ='Weekly Inventory'!E53+'Weekly Inventory'!E55+'Weekly Inventory'!E56+'Weekly Inventory'!E57+'Weekly Inventory'!E60-'Weekly Inventory'!E62 -> 12 | G4: ='Weekly Inventory'!F53+'Weekly Inventory'!F55+'Weekly Inventory'!F56+'Weekly Inventory'!F57+'Weekly Inventory'!F60-'Weekly Inventory'!F62 -> -1 | H4: ='Weekly Inventory'!G53+'Weekly Inventory'!G55+'Weekly Inventory'!G56+'Weekly Inventory'!G57+'Weekly Inventory'!G60-'Weekly Inventory'!G62 -> -6 | I4: ='Weekly Inventory'!H53+'Weekly Inventory'!H55+'Weekly Inventory'!H56+'Weekly Inventory'!H57+'Weekly Inventory'!H60-'Weekly Inventory'!H62 -> 33 | J4: ='Weekly Inventory'!I53+'Weekly Inventory'!I55+'Weekly Inventory'!I56+'Weekly Inventory'!I57+'Weekly Inventory'!I60-'Weekly Inventory'!I62 -> 0 | K4: ='Weekly Inventory'!L53+'Weekly Inventory'!L55+'Weekly Inventory'!L56+'Weekly Inventory'!L57+'Weekly Inventory'!L60-'Weekly Inventory'!L62 -> 115 | L4: ='Weekly Inventory'!M53+'Weekly Inventory'!M55+'Weekly Inventory'!M56+'Weekly Inventory'!M57+'Weekly Inventory'!M60-'Weekly Inventory'!M62 -> 149
A5: 45352 | B5: =sum(C5:Z5) -> 407 | C5: ='Weekly Inventory'!B62+'Weekly Inventory'!B63+'Weekly Inventory'!B65+'Weekly Inventory'!B69-'Weekly Inventory'!B70 -> 52 | D5: ='Weekly Inventory'!C62+'Weekly Inventory'!C63+'Weekly Inventory'!C65+'Weekly Inventory'!C69-'Weekly Inventory'!C70 -> 3 | E5: ='Weekly Inventory'!D62+'Weekly Inventory'!D63+'Weekly Inventory'!D65+'Weekly Inventory'!D69-'Weekly Inventory'!D70 -> 50 | F5: ='Weekly Inventory'!E62+'Weekly Inventory'!E63+'Weekly Inventory'!E65+'Weekly Inventory'!E69-'Weekly Inventory'!E70 -> 84 | G5: ='Weekly Inventory'!F62+'Weekly Inventory'!F63+'Weekly Inventory'!F65+'Weekly Inventory'!F69-'Weekly Inventory'!F70 -> 123 | H5: ='Weekly Inventory'!G62+'Weekly Inventory'!G63+'Weekly Inventory'!G65+'Weekly Inventory'!G69-'Weekly Inventory'!G70 -> 24 | I5: ='Weekly Inventory'!H62+'Weekly Inventory'!H63+'Weekly Inventory'!H65+'Weekly Inventory'!H69-'Weekly Inventory'!H70 -> 53 | J5: ='Weekly Inventory'!I62+'Weekly Inventory'!I63+'Weekly Inventory'!I65+'Weekly Inventory'!I69-'Weekly Inventory'!I70 -> 24 | K5: ='Weekly Inventory'!L62+'Weekly Inventory'!L63+'Weekly Inventory'!L65+'Weekly Inventory'!L69-'Weekly Inventory'!L70 -> 12 | L5: ='Weekly Inventory'!M62+'Weekly Inventory'!M63+'Weekly Inventory'!M65+'Weekly Inventory'!M69-'Weekly Inventory'!M70 -> -18
A6: 45383 | B6: =sum(C6:Z6) -> 220 | C6: ='Weekly Inventory'!B70+'Weekly Inventory'!B72+'Weekly Inventory'!B73+'Weekly Inventory'!B74+'Weekly Inventory'!B76-'Weekly Inventory'!B77 -> 57 | D6: ='Weekly Inventory'!C70+'Weekly Inventory'!C72+'Weekly Inventory'!C73+'Weekly Inventory'!C74+'Weekly Inventory'!C76-'Weekly Inventory'!C77 -> 6 | E6: ='Weekly Inventory'!D70+'Weekly Inventory'!D72+'Weekly Inventory'!D73+'Weekly Inventory'!D74+'Weekly Inventory'!D76-'Weekly Inventory'!D77 -> 30 | F6: ='Weekly Inventory'!E70+'Weekly Inventory'!E72+'Weekly Inventory'!E73+'Weekly Inventory'!E74+'Weekly Inventory'!E76-'Weekly Inventory'!E77 -> -1 | G6: ='Weekly Inventory'!F70+'Weekly Inventory'!F72+'Weekly Inventory'!F73+'Weekly Inventory'!F74+'Weekly Inventory'!F76-'Weekly Inventory'!F77 -> -1 | H6: ='Weekly Inventory'!G70+'Weekly Inventory'!G72+'Weekly Inventory'!G73+'Weekly Inventory'!G74+'Weekly Inventory'!G76-'Weekly Inventory'!G77 -> 20 | I6: ='Weekly Inventory'!H70+'Weekly Inventory'!H72+'Weekly Inventory'!H73+'Weekly Inventory'!H74+'Weekly Inventory'!H76-'Weekly Inventory'!H77 -> 72 | J6: ='Weekly Inventory'!I70+'Weekly Inventory'!I72+'Weekly Inventory'!I73+'Weekly Inventory'!I74+'Weekly Inventory'!I76-'Weekly Inventory'!I77 -> 0 | K6: ='Weekly Inventory'!L70+'Weekly Inventory'!L72+'Weekly Inventory'!L73+'Weekly Inventory'!L74+'Weekly Inventory'!L76-'Weekly Inventory'!L77 -> -1 | L6: ='Weekly Inventory'!M70+'Weekly Inventory'!M72+'Weekly Inventory'!M73+'Weekly Inventory'!M74+'Weekly Inventory'!M76-'Weekly Inventory'!M77 -> 38
A7: 45413 | B7: =sum(C7:Z7) -> 624 | C7: ='Weekly Inventory'!B77+'Weekly Inventory'!B78+'Weekly Inventory'!B80+'Weekly Inventory'!B82-'Weekly Inventory'!B83 -> 66 | D7: ='Weekly Inventory'!C77+'Weekly Inventory'!C78+'Weekly Inventory'!C80+'Weekly Inventory'!C82-'Weekly Inventory'!C83 -> 97 | E7: ='Weekly Inventory'!D77+'Weekly Inventory'!D78+'Weekly Inventory'!D80+'Weekly Inventory'!D82-'Weekly Inventory'!D83 -> 121 | F7: ='Weekly Inventory'!E77+'Weekly Inventory'!E78+'Weekly Inventory'!E80+'Weekly Inventory'!E82-'Weekly Inventory'!E83 -> 8 | G7: ='Weekly Inventory'!F77+'Weekly Inventory'!F78+'Weekly Inventory'!F80+'Weekly Inventory'!F82-'Weekly Inventory'!F83 -> 14 | H7: ='Weekly Inventory'!G77+'Weekly Inventory'!G78+'Weekly Inventory'!G80+'Weekly Inventory'!G82-'Weekly Inventory'!G83 -> 160 | J7: ='Weekly Inventory'!I77+'Weekly Inventory'!I78+'Weekly Inventory'!I80+'Weekly Inventory'!I82-'Weekly Inventory'!I83 -> 0 | K7: ='Weekly Inventory'!L77+'Weekly Inventory'!L78+'Weekly Inventory'!L80+'Weekly Inventory'!L82-'Weekly Inventory'!L83 -> 44 | L7: ='Weekly Inventory'!M77+'Weekly Inventory'!M78+'Weekly Inventory'!M80+'Weekly Inventory'!M82-'Weekly Inventory'!M83 -> 114
A8: 45444 | B8: =sum(C8:Z8) -> 359 | C8: ='Weekly Inventory'!B83+'Weekly Inventory'!B84+'Weekly Inventory'!B85+'Weekly Inventory'!B86-'Weekly Inventory'!B87 -> 64 | D8: ='Weekly Inventory'!C83+'Weekly Inventory'!C84+'Weekly Inventory'!C85+'Weekly Inventory'!C86-'Weekly Inventory'!C87 -> 32 | E8: ='Weekly Inventory'!D83+'Weekly Inventory'!D84+'Weekly Inventory'!D85+'Weekly Inventory'!D86-'Weekly Inventory'!D87 -> 23 | F8: ='Weekly Inventory'!E83+'Weekly Inventory'!E84+'Weekly Inventory'!E85+'Weekly Inventory'!E86-'Weekly Inventory'!E87 -> 6 | G8: ='Weekly Inventory'!F83+'Weekly Inventory'!F84+'Weekly Inventory'!F85+'Weekly Inventory'!F86-'Weekly Inventory'!F87 -> 15 | H8: ='Weekly Inventory'!G83+'Weekly Inventory'!G84+'Weekly Inventory'!G85+'Weekly Inventory'!G86-'Weekly Inventory'!G87 -> 136 | J8: ='Weekly Inventory'!I83+'Weekly Inventory'!I84+'Weekly Inventory'!I85+'Weekly Inventory'!I86-'Weekly Inventory'!I87 -> 2 | K8: ='Weekly Inventory'!L83+'Weekly Inventory'!L84+'Weekly Inventory'!L85+'Weekly Inventory'!L86-'Weekly Inventory'!L87 -> 19 | L8: ='Weekly Inventory'!M83+'Weekly Inventory'!M84+'Weekly Inventory'!M85+'Weekly Inventory'!M86-'Weekly Inventory'!M87 -> 95 | Q8: ='Weekly Inventory'!R83+'Weekly Inventory'!R84+'Weekly Inventory'!R85+'Weekly Inventory'!R86-'Weekly Inventory'!R87 -> -15 | R8: ='Weekly Inventory'!S83+'Weekly Inventory'!S84+'Weekly Inventory'!S85+'Weekly Inventory'!S86-'Weekly Inventory'!S87 -> -18
A9: 45474 | B9: =sum(C9:Z9) -> 215 | C9: ='Weekly Inventory'!B87+'Weekly Inventory'!B88-'Weekly Inventory'!B91 -> 42 | D9: ='Weekly Inventory'!C87+'Weekly Inventory'!C88-'Weekly Inventory'!C91 -> 44 | E9: ='Weekly Inventory'!D87+'Weekly Inventory'!D88-'Weekly Inventory'!D91 -> 42 | F9: ='Weekly Inventory'!E87+'Weekly Inventory'!E88-'Weekly Inventory'!E91 -> 9 | G9: ='Weekly Inventory'!F87+'Weekly Inventory'!F88-'Weekly Inventory'!F91 -> 24 | H9: ='Weekly Inventory'!G87+'Weekly Inventory'!G88-'Weekly Inventory'!G91 -> -33 | J9: ='Weekly Inventory'!I87+'Weekly Inventory'!I88-'Weekly Inventory'!I91 -> 7 | K9: ='Weekly Inventory'!L87+'Weekly Inventory'!L88-'Weekly Inventory'!L91 -> 30 | L9: ='Weekly Inventory'!M87+'Weekly Inventory'!M88-'Weekly Inventory'!M91 -> 8 | M9: ='Weekly Inventory'!N87+'Weekly Inventory'!N88-'Weekly Inventory'!N91 -> 0 | N9: ='Weekly Inventory'!O87+'Weekly Inventory'!O88-'Weekly Inventory'!O91 -> 0 | O9: ='Weekly Inventory'!P87+'Weekly Inventory'!P88-'Weekly Inventory'!P91 -> 0 | Q9: ='Weekly Inventory'!R87+'Weekly Inventory'!R88-'Weekly Inventory'!R91 -> 24 | R9: ='Weekly Inventory'!S87+'Weekly Inventory'!S88-'Weekly Inventory'!S91 -> 18
A10: 45505 | B10: =sum(C10:Z10) -> 532 | C10: ='Weekly Inventory'!B91+'Weekly Inventory'!B92+'Weekly Inventory'!B94+'Weekly Inventory'!B98-'Weekly Inventory'!B99 -> 134 | D10: ='Weekly Inventory'!C91+'Weekly Inventory'!C92+'Weekly Inventory'!C94+'Weekly Inventory'!C98-'Weekly Inventory'!C99 -> 13 | E10: ='Weekly Inventory'!D91+'Weekly Inventory'!D92+'Weekly Inventory'!D94+'Weekly Inventory'!D98-'Weekly Inventory'!D99 -> 80 | F10: ='Weekly Inventory'!E91+'Weekly Inventory'!E92+'Weekly Inventory'!E94+'Weekly Inventory'!E98-'Weekly Inventory'!E99 -> 6 | G10: ='Weekly Inventory'!F91+'Weekly Inventory'!F92+'Weekly Inventory'!F94+'Weekly Inventory'!F98-'Weekly Inventory'!F99 -> 65 | H10: ='Weekly Inventory'!G91+'Weekly Inventory'!G92+'Weekly Inventory'!G94+'Weekly Inventory'!G98-'Weekly Inventory'!G99 -> 57 | I10: ='Weekly Inventory'!H91+'Weekly Inventory'!H92+'Weekly Inventory'!H94+'Weekly Inventory'!H98-'Weekly Inventory'!H99 -> 0 | J10: ='Weekly Inventory'!I91+'Weekly Inventory'!I92+'Weekly Inventory'!I94+'Weekly Inventory'!I98-'Weekly Inventory'!I99 -> 27 | K10: ='Weekly Inventory'!L91+'Weekly Inventory'!L92+'Weekly Inventory'!L94+'Weekly Inventory'!L98-'Weekly Inventory'!L99 -> 90 | L10: ='Weekly Inventory'!M91+'Weekly Inventory'!M92+'Weekly Inventory'!M94+'Weekly Inventory'!M98-'Weekly Inventory'!M99 -> 60 | M10: ='Weekly Inventory'!N91+'Weekly Inventory'!N92+'Weekly Inventory'!N94+'Weekly Inventory'!N98-'Weekly Inventory'!N99 -> 0 | N10: ='Weekly Inventory'!O91+'Weekly Inventory'!O92+'Weekly Inventory'!O94+'Weekly Inventory'!O98-'Weekly Inventory'!O99 -> 0 | O10: ='Weekly Inventory'!P91+'Weekly Inventory'!P92+'Weekly Inventory'!P94+'Weekly Inventory'!P98-'Weekly Inventory'!P99 -> 0 | Q10: ='Weekly Inventory'!Q91+'Weekly Inventory'!Q92+'Weekly Inventory'!Q94+'Weekly Inventory'!Q98-'Weekly Inventory'!Q99 -> 0 | R10: ='Weekly Inventory'!R91+'Weekly Inventory'!R92+'Weekly Inventory'!R94+'Weekly Inventory'!R98-'Weekly Inventory'!R99 -> 0
A11: 45536 | B11: =sum(C11:Z11) -> 282 | C11: ='Weekly Inventory'!B99+'Weekly Inventory'!B100+'Weekly Inventory'!B101+'Weekly Inventory'!B102-'Weekly Inventory'!B103 -> -7 | D11: ='Weekly Inventory'!C99+'Weekly Inventory'!C100+'Weekly Inventory'!C101+'Weekly Inventory'!C102-'Weekly Inventory'!C103 -> 16 | E11: ='Weekly Inventory'!D99+'Weekly Inventory'!D100+'Weekly Inventory'!D101+'Weekly Inventory'!D102-'Weekly Inventory'!D103 -> 117 | F11: ='Weekly Inventory'!E99+'Weekly Inventory'!E100+'Weekly Inventory'!E101+'Weekly Inventory'!E102-'Weekly Inventory'!E103 -> 22 | G11: ='Weekly Inventory'!F99+'Weekly Inventory'!F100+'Weekly Inventory'!F101+'Weekly Inventory'!F102-'Weekly Inventory'!F103 -> 0 | H11: ='Weekly Inventory'!G99+'Weekly Inventory'!G100+'Weekly Inventory'!G101+'Weekly Inventory'!G102-'Weekly Inventory'!G103 -> 79 | I11: ='Weekly Inventory'!H99+'Weekly Inventory'!H100+'Weekly Inventory'!H101+'Weekly Inventory'!H102-'Weekly Inventory'!H103 -> -3 | J11: ='Weekly Inventory'!I99+'Weekly Inventory'!I100+'Weekly Inventory'!I101+'Weekly Inventory'!I102-'Weekly Inventory'!I103 -> 13 | K11: ='Weekly Inventory'!L99+'Weekly Inventory'!L100+'Weekly Inventory'!L101+'Weekly Inventory'!L102-'Weekly Inventory'!L103 -> 38 | L11: ='Weekly Inventory'!M99+'Weekly Inventory'!M100+'Weekly Inventory'!M101+'Weekly Inventory'!M102-'Weekly Inventory'!M103 -> 6 | M11: ='Weekly Inventory'!N99+'Weekly Inventory'!N100+'Weekly Inventory'!N101+'Weekly Inventory'!N102-'Weekly Inventory'!N103 -> 0 | N11: ='Weekly Inventory'!O99+'Weekly Inventory'!O100+'Weekly Inventory'!O101+'Weekly Inventory'!O102-'Weekly Inventory'!O103 -> 0 | O11: ='Weekly Inventory'!P99+'Weekly Inventory'!P100+'Weekly Inventory'!P101+'Weekly Inventory'!P102-'Weekly Inventory'!P103 -> 0 | P11: ='Weekly Inventory'!Q99+'Weekly Inventory'!Q100+'Weekly Inventory'!Q101+'Weekly Inventory'!Q102-'Weekly Inventory'!Q103 -> 0 | Q11: ='Weekly Inventory'!R99+'Weekly Inventory'!R100+'Weekly Inventory'!R101+'Weekly Inventory'!R102-'Weekly Inventory'!R103 -> 0 | R11: ='Weekly Inventory'!S99+'Weekly Inventory'!S100+'Weekly Inventory'!S101+'Weekly Inventory'!S102-'Weekly Inventory'!S103 -> 0 | ... V11: ='Weekly Inventory'!W99+'Weekly Inventory'!W100+'Weekly Inventory'!W101+'Weekly Inventory'!W102-'Weekly Inventory'!W103 -> 0 | W11: ='Weekly Inventory'!Y99+'Weekly Inventory'!Y100+'Weekly Inventory'!Y101+'Weekly Inventory'!Y102-'Weekly Inventory'!Y103 -> 0 | X11: ='Weekly Inventory'!Z99+'Weekly Inventory'!Z100+'Weekly Inventory'!Z101+'Weekly Inventory'!Z102-'Weekly Inventory'!Z103 -> 0 | AG11: ='Weekly Inventory'!AH99+'Weekly Inventory'!AH100+'Weekly Inventory'!AH101+'Weekly Inventory'!AH102-'Weekly Inventory'!AH103 -> 0
A12: 45566 | B12: =sum(C12:Z12) -> 354 | C12: ='Weekly Inventory'!B103+'Weekly Inventory'!B104+'Weekly Inventory'!B108-'Weekly Inventory'!B109 -> 74 | D12: ='Weekly Inventory'!C103+'Weekly Inventory'!C104+'Weekly Inventory'!C108-'Weekly Inventory'!C109 -> 83 | E12: ='Weekly Inventory'!D103+'Weekly Inventory'!D104+'Weekly Inventory'!D108-'Weekly Inventory'!D109 -> 59 | F12: ='Weekly Inventory'!E103+'Weekly Inventory'!E104+'Weekly Inventory'!E108-'Weekly Inventory'!E109 -> 9 | G12: ='Weekly Inventory'!F103+'Weekly Inventory'!F104+'Weekly Inventory'!F108-'Weekly Inventory'!F109 -> 0 | H12: ='Weekly Inventory'!G103+'Weekly Inventory'!G104+'Weekly Inventory'!G108-'Weekly Inventory'!G109 -> 20 | I12: ='Weekly Inventory'!H103+'Weekly Inventory'!H104+'Weekly Inventory'!H108-'Weekly Inventory'!H109 -> 37 | J12: ='Weekly Inventory'!I103+'Weekly Inventory'!I104+'Weekly Inventory'!I108-'Weekly Inventory'!I109 -> 15 | K12: ='Weekly Inventory'!L103+'Weekly Inventory'!L104+'Weekly Inventory'!L108-'Weekly Inventory'!L109 -> -9 | L12: ='Weekly Inventory'!M103+'Weekly Inventory'!M104+'Weekly Inventory'!M108-'Weekly Inventory'!M109 -> 50 | M12: ='Weekly Inventory'!N103+'Weekly Inventory'!N104+'Weekly Inventory'!N108-'Weekly Inventory'!N109 -> 0 | N12: ='Weekly Inventory'!O103+'Weekly Inventory'!O104+'Weekly Inventory'!O108-'Weekly Inventory'!O109 -> 0 | O12: ='Weekly Inventory'!P103+'Weekly Inventory'!P104+'Weekly Inventory'!P108-'Weekly Inventory'!P109 -> 0 | P12: ='Weekly Inventory'!Q103+'Weekly Inventory'!Q104+'Weekly Inventory'!Q108-'Weekly Inventory'!Q109 -> 0 | Q12: ='Weekly Inventory'!R103+'Weekly Inventory'!R104+'Weekly Inventory'!R108-'Weekly Inventory'!R109 -> 0 | R12: ='Weekly Inventory'!S103+'Weekly Inventory'!S104+'Weekly Inventory'!S108-'Weekly Inventory'!S109 -> 0 | ... V12: ='Weekly Inventory'!W103+'Weekly Inventory'!W104+'Weekly Inventory'!W108-'Weekly Inventory'!W109 -> 0 | W12: ='Weekly Inventory'!Y103+'Weekly Inventory'!Y104+'Weekly Inventory'!Y108-'Weekly Inventory'!Y109 -> 0 | X12: ='Weekly Inventory'!Z103+'Weekly Inventory'!Z104+'Weekly Inventory'!Z108-'Weekly Inventory'!Z109 -> 0 | Y12: ='Weekly Inventory'!J103+'Weekly Inventory'!J104+'Weekly Inventory'!J108-'Weekly Inventory'!J109 -> 0 | Z12: ='Weekly Inventory'!AA103+'Weekly Inventory'!AA104+'Weekly Inventory'!AA108-'Weekly Inventory'!AA109 -> 0 | AG12: ='Weekly Inventory'!AH103+'Weekly Inventory'!AH104-'Weekly Inventory'!AH105 -> 0
A13: 45597 | B13: =sum(C13:Z13) -> 152 | C13: ='Weekly Inventory'!B109+'Weekly Inventory'!B110-'Weekly Inventory'!B111 -> 19 | D13: ='Weekly Inventory'!C109+'Weekly Inventory'!C110-'Weekly Inventory'!C111 -> 32 | E13: ='Weekly Inventory'!D109+'Weekly Inventory'!D110-'Weekly Inventory'!D111 -> 33 | F13: ='Weekly Inventory'!E109+'Weekly Inventory'!E110-'Weekly Inventory'!E111 -> -4 | G13: ='Weekly Inventory'!F109+'Weekly Inventory'!F110-'Weekly Inventory'!F111 -> 0 | H13: ='Weekly Inventory'!G109+'Weekly Inventory'!G110-'Weekly Inventory'!G111 -> 16 | I13: ='Weekly Inventory'!H109+'Weekly Inventory'!H110-'Weekly Inventory'!H111 -> 18 | J13: ='Weekly Inventory'!I109+'Weekly Inventory'!I110-'Weekly Inventory'!I111 -> 24 | K13: ='Weekly Inventory'!L109+'Weekly Inventory'!L110-'Weekly Inventory'!L111 -> 9 | L13: ='Weekly Inventory'!M109+'Weekly Inventory'!M110-'Weekly Inventory'!M111 -> 5 | M13: ='Weekly Inventory'!N109+'Weekly Inventory'!N110-'Weekly Inventory'!N111 -> 0 | N13: ='Weekly Inventory'!O109+'Weekly Inventory'!O110-'Weekly Inventory'!O111 -> 0 | O13: ='Weekly Inventory'!P109+'Weekly Inventory'!P110-'Weekly Inventory'!P111 -> 0 | P13: ='Weekly Inventory'!Q109+'Weekly Inventory'!Q110-'Weekly Inventory'!Q111 -> 0 | Q13: ='Weekly Inventory'!R109+'Weekly Inventory'!R110-'Weekly Inventory'!R111 -> 0 | R13: ='Weekly Inventory'!S109+'Weekly Inventory'!S110-'Weekly Inventory'!S111 -> 0 | ... V13: ='Weekly Inventory'!W109+'Weekly Inventory'!W110-'Weekly Inventory'!W111 -> 0 | W13: ='Weekly Inventory'!Y109+'Weekly Inventory'!Y110-'Weekly Inventory'!Y111 -> 0 | X13: ='Weekly Inventory'!Z109+'Weekly Inventory'!Z110-'Weekly Inventory'!Z111 -> 0 | Y13: ='Weekly Inventory'!J109+'Weekly Inventory'!J110-'Weekly Inventory'!J111 -> 0 | Z13: ='Weekly Inventory'!AA109+'Weekly Inventory'!AA110-'Weekly Inventory'!AA111 -> 0
A15: Average | B15: =MEDIAN(B2:B13) -> 318 | C15: =MEDIAN(C2:C13) -> 54.5 | D15: =MEDIAN(D2:D13) -> 29 | E15: =MEDIAN(E2:E13) -> 46 | F15: =MEDIAN(F2:F13) -> 9 | G15: =MEDIAN(G2:G13) -> 0 | H15: =MEDIAN(H2:H13) -> 22 | I15: =MEDIAN(I2:I13) -> 18 | ... Z15: =MEDIAN(Z2:Z13) -> 0
A16: Current | C16: ='Weekly Inventory'!B109 | D16: ='Weekly Inventory'!C109 | E16: ='Weekly Inventory'!D109 | F16: ='Weekly Inventory'!E109 | G16: ='Weekly Inventory'!F109 | H16: ='Weekly Inventory'!G109 | I16: ='Weekly Inventory'!H109 | J16: ='Weekly Inventory'!I109 -> 24 | K16: ='Weekly Inventory'!L109 -> 9 | L16: ='Weekly Inventory'!M109 | M16: ='Weekly Inventory'!N109 | N16: ='Weekly Inventory'!O109 | O16: ='Weekly Inventory'!P109 | P16: ='Weekly Inventory'!Q109 | Q16: ='Weekly Inventory'!R109 | R16: ='Weekly Inventory'!S109 | S16: ='Weekly Inventory'!T109 | T16: ='Weekly Inventory'!U105 -> 3 | U16: ='Weekly Inventory'!V105 | V16: ='Weekly Inventory'!W105 | W16: ='Weekly Inventory'!Y105 | X16: ='Weekly Inventory'!Z105 | Y16: ='Weekly Inventory'!J109
B17: =SUM(B2:B13) -> 3961 | C17: =C16/C15 -> 0 | D17: =D16/D15 -> 0 | E17: =E16/E15 -> 0 | F17: =F16/F15 -> 0 | G17: =G16/G15 -> #DIV/0! | H17: =H16/H15 -> 0 | I17: =I16/I15 -> 0 | J17: =J16/J15 -> 3.4285714 | ... X17: =X16/X15 -> #DIV/0!
G20: =SUM(Table2[Gin 1]) -> 239 | H20: =SUM(Table2[Gin 2]) -> 570
C21: =SUM(Table2[Vodka]) -> 634

Sheet Sheet3
B3: November | C3: December | D3: January | E3: February | F3: March | G3: April | H3: May | I3: June
A4: Start | B4: 56.07 | C4: =B7 -> 95.71 | D4: =C7 -> 80.65 | E4: =D7 -> 97.09 | F4: =E7 -> 124.24 | G4: =F7 -> 178.53 | H4: =G7 -> 177.34 | I4: =H7
A5: Produced | B5: 59.45 | C5: 22.99 | D5: 30.52 | E5: 61.43 | F5: 76.68 | G5: 31.31
A6: Used | B6: =B7-B4-B5 -> -19.81 | C6: =C7-C4-C5 -> -38.05 | D6: =D7-D4-D5 -> -14.08 | E6: =E7-E4-E5 -> -34.28 | F6: =F7-F4-F5 -> -22.39 | G6: =G7-G4-G5 -> -32.5 | H6: =H7-H4-H5 -> -177.34 | I6: =I7-I4-I5 -> 0
A7: End | B7: 95.71 | C7: 80.65 | D7: 97.09 | E7: 124.24 | F7: 178.53 | G7: 177.34
B9: Done | C9: Done | D9: Done | E9: Done | F9: Done | G9: Done
